Workbook
Name Delivery_Cost: 'Master Data'!$B$142:$B$196
Name Labour_Cost: 'Master Data'!$B$111
Name Labour_Cost_Working: 'Master Data'!$X$109
Name Maruthi_Plastics_Packing_Material_Cost: 'Master Data'!$D$201
Name Masala_and_Blends_Costings: 'Master Data'!$A$551
Name No._Of_Units_Of_PM_Required_for_Selected_Retail_Packs: 'Master Data'!$C$322
Name Packaging_Cost: 'Master Data'!$B$115:$B$139
Name Raw_Material_Cost: 'Master Data'!$B$22:$B$110
Name Raw_Material_source_costs: 'Master Data'!$453:$541
Name Size_in_grams: 'Master Data'!$U$1171:$U$1180
Name Swiss_Pac_Packing_Material_Cost: 'Master Data'!$D$260
Name Vendor_Transport_Costs: 'Master Data'!$433:$447

Sheet Cost Sheet
A1: 1 | B1: =+A1+1 -> 2 | C1: =+B1+1 -> 3 | D1: =+C1+1 -> 4 | E1: =+D1+1 -> 5 | F1: =+E1+1 -> 6 | G1: =+F1+1 -> 7 | H1: =+G1+1 -> 8 | I1: =+H1+1 -> 9 | ... V1: =+U1+1 -> 22
A2: Sr. No. | B2: Item | C2: Name in Hindi | D2: Sources | E2: Landed Cost of Goods With GST Per Gm | F2: Landed Cost of Goods With GST Per Kg | G2: No. Of Retail Packs Per Kg | H2: No. Of Units Of PM Required for Selected Retail Packs | I2: Packing Material | J2: Packing Material for Shipping | K2: Shipping/Postage | L2: Miscellaneous Costs Percentage | M2: Qty per Pack | N2: Packaging Cost Per Retail Pack | O2: Packaging Cost With GST | P2: Cost of sticker with GST | Q2: Total Labour Cost | R2: Storage Cost | S2: Packaging Material for Shipping With GST | T2: Shipping/Postage With GST | U2: Miscellaneous Costs | V2: Total Cost Per Kg
A3: 1 | B3: Black Cardamom | C3: काली इलाइची | D3: =+VLOOKUP($B3,'Master Data'!$B$20:$W$197,2,FALSE) -> Ali Kikabai | E3: =+VLOOKUP($B3,'Master Data'!$B:$V,21,FALSE) -> 1.9586 | F3: =+E3*1000 -> 1958.6 | G3: 0.5 | H3: =+IF($G3=0.5,1,IF($G3=1,2,$G3)) -> 1 | I3: One side Transparent Stand Up with Zipper (25Gm-100Gm) | J3: Five Ply Box | K3: Surface Xpressbees 0.5Kg-Within City | L3: 15 | M3: =1000/G3 -> 2000 | N3: =+VLOOKUP($I3,'Master Data'!$B:$V,21,FALSE) -> 2.23 | O3: =+N3*H3 -> 2.23 | P3: =+'Master Data'!$W$127*$H3 -> 2.2 | Q3: =+'Master Data'!$W$111*$H3 -> 3.0769231 | R3: 0 | S3: =+VLOOKUP($J3,'Master Data'!$B:$V,21,FALSE)*$H3 -> 55.02 | T3: =+VLOOKUP($K3,'Master Data'!$B:$V,21,FALSE) -> 30 | U3: =+($F3+$O3+$P3+$S3)*($L3/100) -> 302.7075 | V3: =+$F3+$O3+$P3+$Q3+$R3+$S3+$T3+$U3 -> 2353.8344
A4: =+A3+1 -> 2 | B4: Green Cardamom | C4: इलायची | D4: Chandan Enterprise | E4: =+VLOOKUP($B4,'Master Data'!$B:$V,21,FALSE) -> 3.141 | F4: =+E4*1000 -> 3141 | G4: 1 | H4: =+IF($G4=0.5,1,IF($G4=1,2,$G4)) -> 2 | I4: One side Transparent Flat Bottom with Zipper (1000Gm) | J4: Recycle Box | K4: NA | L4: 25 | M4: =1000/G4 -> 1000 | N4: =+VLOOKUP($I4,'Master Data'!$B:$V,21,FALSE)*H4 -> 23.88 | O4: =+N4*G4 -> 23.88 | P4: =+'Master Data'!$W$127*$H4 -> 4.4 | Q4: =+'Master Data'!$W$111*$H4 -> 6.1538462 | R4: 0 | S4: =+VLOOKUP($J4,'Master Data'!$B:$V,21,FALSE)*$H4 -> 0 | T4: =+VLOOKUP($K4,'Master Data'!$B:$V,21,FALSE) -> #N/A | U4: =+($F4+$O4+$P4+$S4)*0.25 -> 792.32 | V4: =+$F4+$O4+$P4+$Q4+$R4+$S4+$T4+$U4 -> #N/A
A5: =+A4+1 -> 3 | B5: Cassia Cinnamon Flakes | C5: कासिया दालचीनी | D5: =+VLOOKUP($B5,'Master Data'!$B$20:$W$197,2,FALSE) -> #N/A | E5: =+VLOOKUP($B5,'Master Data'!$B:$V,21,FALSE) -> #N/A | F5: =+E5*1000 -> #N/A | G5: 1 | H5: =+IF($G5=0.5,2,IF($G5=1,4,$G5)) -> 4 | I5: Brown Kraft Paper with Window & Zipper (25Gm-100Gm) | J5: Bubble Pouch Small | K5: Surface Xpressbees 0.5Kg-Within City | L5: 15 | M5: =1000/G5 -> 1000 | N5: =+VLOOKUP($I5,'Master Data'!$B:$V,21,FALSE) -> 3.16 | O5: =+N5*G5 -> 3.16 | P5: =+'Master Data'!$W$127*$G5 -> 2.2 | Q5: =+'Master Data'!$W$111*$G5 -> 3.0769231 | R5: 0 | S5: =+VLOOKUP($J5,'Master Data'!$B:$V,21,FALSE)*$H5 -> 35.08 | T5: =+VLOOKUP($K5,'Master Data'!$B:$V,21,FALSE) -> 30 | U5: =+($F5+$O5+$P5+$S5)*0.15 -> #N/A | V5: =+$F5+$O5+$P5+$Q5+$R5+$S5+$T5+$U5 -> #N/A
A6: =+A5+1 -> 4 | B6: Cloves | C6: लौंग | D6: =+VLOOKUP($B6,'Master Data'!$B$20:$W$197,2,FALSE) -> Nadha Spices | E6: =+VLOOKUP($B6,'Master Data'!$B:$V,21,FALSE) -> 1.191 | F6: =+E6*1000 -> 1191 | G6: 40 | H6: =+IF($G6=0.5,1,IF($G6=1,1,$G6)) -> 40 | I6: Brown Kraft Paper with Window & Zipper (25Gm-100Gm) | J6: Bubble Pouch Medium | K6: Surface Xpressbees 1Kg-NE,J&K,KL,AN | L6: 40 | M6: =1000/G6 -> 25 | N6: =+VLOOKUP($I6,'Master Data'!$B:$V,21,FALSE) -> 3.16 | O6: =+N6*G6 -> 126.4 | P6: =+'Master Data'!$W$127*$G6 -> 88 | Q6: =+'Master Data'!$W$111*$G6 -> 123.07692 | R6: 0 | S6: =+VLOOKUP($J6,'Master Data'!$B:$V,21,FALSE)*$H6 -> 472 | T6: =+VLOOKUP($K6,'Master Data'!$B:$V,21,FALSE) -> 98 | U6: =+($F6+$O6+$P6+$S6)*0.15 -> 281.61 | V6: =+$F6+$O6+$P6+$Q6+$R6+$S6+$T6+$U6 -> 2380.0869
A7: =+A6+1 -> 5 | B7: Original Indian Bay Leaf | C7: तेज पत्ता | D7: =+VLOOKUP($B7,'Master Data'!$B$20:$W$197,2,FALSE) -> Ali Kikabai | E7: =+VLOOKUP($B7,'Master Data'!$B:$V,21,FALSE) -> 0.1736 | F7: =+E7*1000 -> 173.6 | G7: 1 | H7: =+IF($G7=0.5,2,IF($G7=1,4,$G7)) -> 4 | I7: Brown Kraft Paper with Window & Zipper (25Gm-100Gm) | J7: Bubble Pouch Small | K7: Surface Xpressbees 0.5Kg-Within City | L7: 15 | M7: =1000/G7 -> 1000 | N7: =+VLOOKUP($I7,'Master Data'!$B:$V,21,FALSE) -> 3.16 | O7: =+N7*G7 -> 3.16 | P7: =+'Master Data'!$W$127*$G7 -> 2.2 | Q7: =+'Master Data'!$W$111*$G7 -> 3.0769231 | R7: 0 | S7: =+VLOOKUP($J7,'Master Data'!$B:$V,21,FALSE)*$H7 -> 35.08 | T7: =+VLOOKUP($K7,'Master Data'!$B:$V,21,FALSE) -> 30 | U7: =+($F7+$O7+$P7+$S7)*0.15 -> 32.106 | V7: =+$F7+$O7+$P7+$Q7+$R7+$S7+$T7+$U7 -> 279.22292
A8: =+A7+1 -> 6 | B8: Original Kerala Cinnamon Flakes | C8: केरला दालचीनी | D8: =+VLOOKUP($B8,'Master Data'!$B$20:$W$197,2,FALSE) -> Eternal Blooms | E8: =+VLOOKUP($B8,'Master Data'!$B:$V,21,FALSE) -> 1.006 | F8: =+E8*1000 -> 1006 | G8: 1 | H8: =+IF($G8=0.5,2,IF($G8=1,4,$G8)) -> 4 | I8: Brown Kraft Paper with Window & Zipper (25Gm-100Gm) | J8: Bubble Pouch Small | K8: Surface Xpressbees 0.5Kg-Within City | L8: 15 | M8: =1000/G8 -> 1000 | N8: =+VLOOKUP($I8,'Master Data'!$B:$V,21,FALSE) -> 3.16 | O8: =+N8*G8 -> 3.16 | P8: =+'Master Data'!$W$127*$G8 -> 2.2 | Q8: =+'Master Data'!$W$111*$G8 -> 3.0769231 | R8: 0 | S8: =+VLOOKUP($J8,'Master Data'!$B:$V,21,FALSE)*$H8 -> 35.08 | T8: =+VLOOKUP($K8,'Master Data'!$B:$V,21,FALSE) -> 30 | U8: =+($F8+$O8+$P8+$S8)*0.15 -> 156.966 | V8: =+$F8+$O8+$P8+$Q8+$R8+$S8+$T8+$U8 -> 1236.4829
A9: =+A8+1 -> 7 | B9: Red Chilli Whole - Byadagi | C9: लाल मिर्च - ब्याडगी | D9: =+VLOOKUP($B9,'Master Data'!$B$20:$W$197,2,FALSE) -> MS Malagi | E9: =+VLOOKUP($B9,'Master Data'!$B:$V,21,FALSE) -> 0.611 | F9: =+E9*1000 -> 611 | G9: 1 | H9: =+IF($G9=0.5,2,IF($G9=1,4,$G9)) -> 4 | I9: Brown Kraft Paper with Window & Zipper (25Gm-100Gm) | J9: Bubble Pouch Small | K9: Surface Xpressbees 0.5Kg-Within City | L9: 15 | M9: =1000/G9 -> 1000 | N9: =+VLOOKUP($I9,'Master Data'!$B:$V,21,FALSE) -> 3.16 | O9: =+N9*G9 -> 3.16 | P9: =+'Master Data'!$W$127*$G9 -> 2.2 | Q9: =+'Master Data'!$W$111*$G9 -> 3.0769231 | R9: 0 | S9: =+VLOOKUP($J9,'Master Data'!$B:$V,21,FALSE)*$H9 -> 35.08 | T9: =+VLOOKUP($K9,'Master Data'!$B:$V,21,FALSE) -> 30 | U9: =+($F9+$O9+$P9+$S9)*0.15 -> 97.716 | V9: =+$F9+$O9+$P9+$Q9+$R9+$S9+$T9+$U9 -> 782.23292
A10: =+A9+1 -> 8 | B10: Red Chilli Whole - Kashmiri | C10: लाल मिर्च - कश्मीरी | D10: =+VLOOKUP($B10,'Master Data'!$B$20:$W$197,2,FALSE) -> MS Malagi | E10: =+VLOOKUP($B10,'Master Data'!$B:$V,21,FALSE) -> 0.641 | F10: =+E10*1000 -> 641 | G10: 1 | H10: =+IF($G10=0.5,2,IF($G10=1,4,$G10)) -> 4 | I10: Brown Kraft Paper with Window & Zipper (25Gm-100Gm) | J10: Bubble Pouch Small | K10: Surface Xpressbees 0.5Kg-Within City | L10: 15 | M10: =1000/G10 -> 1000 | N10: =+VLOOKUP($I10,'Master Data'!$B:$V,21,FALSE) -> 3.16 | O10: =+N10*G10 -> 3.16 | P10: =+'Master Data'!$W$127*$G10 -> 2.2 | Q10: =+'Master Data'!$W$111*$G10 -> 3.0769231 | R10: 0 | S10: =+VLOOKUP($J10,'Master Data'!$B:$V,21,FALSE)*$H10 -> 35.08 | T10: =+VLOOKUP($K10,'Master Data'!$B:$V,21,FALSE) -> 30 | U10: =+($F10+$O10+$P10+$S10)*0.15 -> 102.216 | V10: =+$F10+$O10+$P10+$Q10+$R10+$S10+$T10+$U10 -> 816.73292
A11: =+A10+1 -> 9 | B11: Black Pepper Whole | C11: काली मिर्च | D11: =+VLOOKUP($B11,'Master Data'!$B$20:$W$197,2,FALSE) -> Nadha Spices | E11: =+VLOOKUP($B11,'Master Data'!$B:$V,21,FALSE) -> 0.881 | F11: =+E11*1000 -> 881 | G11: 1 | H11: =+IF($G11=0.5,1,IF($G11=1,1,$G11)) -> 1 | I11: Brown Kraft Paper with Window & Zipper (25Gm-100Gm) | J11: Bubble Pouch Small | K11: Surface Xpressbees 0.5Kg-Within City | L11: 15 | M11: =1000/G11 -> 1000 | N11: =+VLOOKUP($I11,'Master Data'!$B:$V,21,FALSE) -> 3.16 | O11: =+N11*G11 -> 3.16 | P11: =+'Master Data'!$W$127*$G11 -> 2.2 | Q11: =+'Master Data'!$W$111*$G11 -> 3.0769231 | R11: 0 | S11: =+VLOOKUP($J11,'Master Data'!$B:$V,21,FALSE)*$H11 -> 8.77 | T11: =+VLOOKUP($K11,'Master Data'!$B:$V,21,FALSE) -> 30 | U11: =+($F11+$O11+$P11+$S11)*0.15 -> 134.2695 | V11: =+$F11+$O11+$P11+$Q11+$R11+$S11+$T11+$U11 -> 1062.4764
A12: =+A11+1 -> 10 | B12: Coriander Seeds | C12: धनिया | D12: =+VLOOKUP($B12,'Master Data'!$B$20:$W$197,2,FALSE) -> Chandan Enterprise | E12: =+VLOOKUP($B12,'Master Data'!$B:$V,21,FALSE) -> 0.192 | F12: =+E12*1000 -> 192 | G12: 1 | H12: =+IF($G12=0.5,1,IF($G12=1,2,$G12)) -> 2 | I12: Brown Kraft Paper with Window & Zipper (25Gm-100Gm) | J12: Bubble Pouch Small | K12: Surface Xpressbees 0.5Kg-Within City | L12: 15 | M12: =1000/G12 -> 1000 | N12: =+VLOOKUP($I12,'Master Data'!$B:$V,21,FALSE) -> 3.16 | O12: =+N12*G12 -> 3.16 | P12: =+'Master Data'!$W$127*$G12 -> 2.2 | Q12: =+'Master Data'!$W$111*$G12 -> 3.0769231 | R12: 0 | S12: =+VLOOKUP($J12,'Master Data'!$B:$V,21,FALSE)*$H12 -> 17.54 | T12: =+VLOOKUP($K12,'Master Data'!$B:$V,21,FALSE) -> 30 | U12: =+($F12+$O12+$P12+$S12)*0.15 -> 32.235 | V12: =+$F12+$O12+$P12+$Q12+$R12+$S12+$T12+$U12 -> 280.21192
A13: =+A12+1 -> 11 | B13: Cumin Seeds | C13: जीरा | D13: =+VLOOKUP($B13,'Master Data'!$B$20:$W$197,2,FALSE) -> Chandan Enterprise | E13: =+VLOOKUP($B13,'Master Data'!$B:$V,21,FALSE) -> 0.304 | F13: =+E13*1000 -> 304 | G13: 1 | H13: =+IF($G13=0.5,1,IF($G13=1,1,$G13)) -> 1 | I13: Brown Kraft Paper with Window & Zipper (25Gm-100Gm) | J13: Bubble Pouch Small | K13: Surface Xpressbees 0.5Kg-Within City | L13: 15 | M13: =1000/G13 -> 1000 | N13: =+VLOOKUP($I13,'Master Data'!$B:$V,21,FALSE) -> 3.16 | O13: =+N13*G13 -> 3.16 | P13: =+'Master Data'!$W$127*$G13 -> 2.2 | Q13: =+'Master Data'!$W$111*$G13 -> 3.0769231 | R13: 0 | S13: =+VLOOKUP($J13,'Master Data'!$B:$V,21,FALSE)*$H13 -> 8.77 | T13: =+VLOOKUP($K13,'Master Data'!$B:$V,21,FALSE) -> 30 | U13: =+($F13+$O13+$P13+$S13)*0.15 -> 47.7195 | V13: =+$F13+$O13+$P13+$Q13+$R13+$S13+$T13+$U13 -> 398.92642
A14: =+A13+1 -> 12 | B14: Mustard Seeds | C14: राइ | D14: =+VLOOKUP($B14,'Master Data'!$B$20:$W$197,2,FALSE) -> Chandan Enterprise | E14: =+VLOOKUP($B14,'Master Data'!$B:$V,21,FALSE) -> 0.132 | F14: =+E14*1000 -> 132 | G14: 1 | H14: =+IF($G14=0.5,1,IF($G14=1,1,$G14)) -> 1 | I14: Brown Kraft Paper with Window & Zipper (25Gm-100Gm) | J14: Bubble Pouch Small | K14: Surface Xpressbees 0.5Kg-Within City | L14: 15 | M14: =1000/G14 -> 1000 | N14: =+VLOOKUP($I14,'Master Data'!$B:$V,21,FALSE) -> 3.16 | O14: =+N14*G14 -> 3.16 | P14: =+'Master Data'!$W$127*$G14 -> 2.2 | Q14: =+'Master Data'!$W$111*$G14 -> 3.0769231 | R14: 0 | S14: =+VLOOKUP($J14,'Master Data'!$B:$V,21,FALSE)*$H14 -> 8.77 | T14: =+VLOOKUP($K14,'Master Data'!$B:$V,21,FALSE) -> 30 | U14: =+($F14+$O14+$P14+$S14)*0.15 -> 21.9195 | V14: =+$F14+$O14+$P14+$Q14+$R14+$S14+$T14+$U14 -> 201.12642
A15: =+A14+1 -> 13 | B15: Mace | C15: जावित्री | D15: =+VLOOKUP($B15,'Master Data'!$B$20:$W$197,2,FALSE) -> Eternal Blooms | E15: =+VLOOKUP($B15,'Master Data'!$B:$V,21,FALSE) -> 2.741 | F15: =+E15*1000 -> 2741 | G15: 1 | H15: =+IF($G15=0.5,2,IF($G15=1,4,$G15)) -> 4 | I15: Brown Kraft Paper with Window & Zipper (25Gm-100Gm) | J15: Bubble Pouch Small | K15: Surface Xpressbees 0.5Kg-Within City | L15: 15 | M15: =1000/G15 -> 1000 | N15: =+VLOOKUP($I15,'Master Data'!$B:$V,21,FALSE) -> 3.16 | O15: =+N15*G15 -> 3.16 | P15: =+'Master Data'!$W$127*$G15 -> 2.2 | Q15: =+'Master Data'!$W$111*$G15 -> 3.0769231 | R15: 0 | S15: =+VLOOKUP($J15,'Master Data'!$B:$V,21,FALSE)*$H15 -> 35.08 | T15: =+VLOOKUP($K15,'Master Data'!$B:$V,21,FALSE) -> 30 | U15: =+($F15+$O15+$P15+$S15)*0.15 -> 417.216 | V15: =+$F15+$O15+$P15+$Q15+$R15+$S15+$T15+$U15 -> 3231.7329
A16: =+A15+1 -> 14 | B16: Nutmeg | C16: जायफल | D16: =+VLOOKUP($B16,'Master Data'!$B$20:$W$197,2,FALSE) -> Nadha Spices | E16: =+VLOOKUP($B16,'Master Data'!$B:$V,21,FALSE) -> 0.941 | F16: =+E16*1000 -> 941 | G16: 1 | H16: =+IF($G16=0.5,1,IF($G16=1,2,$G16)) -> 2 | I16: Brown Kraft Paper with Window & Zipper (25Gm-100Gm) | J16: Bubble Pouch Small | K16: Surface Xpressbees 0.5Kg-Within City | L16: 15 | M16: =1000/G16 -> 1000 | N16: =+VLOOKUP($I16,'Master Data'!$B:$V,21,FALSE) -> 3.16 | O16: =+N16*G16 -> 3.16 | P16: =+'Master Data'!$W$127*$G16 -> 2.2 | Q16: =+'Master Data'!$W$111*$G16 -> 3.0769231 | R16: 0 | S16: =+VLOOKUP($J16,'Master Data'!$B:$V,21,FALSE)*$H16 -> 17.54 | T16: =+VLOOKUP($K16,'Master Data'!$B:$V,21,FALSE) -> 30 | U16: =+($F16+$O16+$P16+$S16)*0.15 -> 144.585 | V16: =+$F16+$O16+$P16+$Q16+$R16+$S16+$T16+$U16 -> 1141.5619
A17: =+A16+1 -> 15 | B17: Star Anise | C17: चक्र फूल | D17: =+VLOOKUP($B17,'Master Data'!$B$20:$W$197,2,FALSE) -> Ali Kikabai | E17: =+VLOOKUP($B17,'Master Data'!$B:$V,21,FALSE) -> 0.5196 | F17: =+E17*1000 -> 519.6 | G17: 1 | H17: =+IF($G17=0.5,1,IF($G17=1,2,$G17)) -> 2 | I17: Brown Kraft Paper with Window & Zipper (25Gm-100Gm) | J17: Bubble Pouch Small | K17: Surface Xpressbees 0.5Kg-Within City | L17: 15 | M17: =1000/G17 -> 1000 | N17: =+VLOOKUP($I17,'Master Data'!$B:$V,21,FALSE) -> 3.16 | O17: =+N17*G17 -> 3.16 | P17: =+'Master Data'!$W$127*$G17 -> 2.2 | Q17: =+'Master Data'!$W$111*$G17 -> 3.0769231 | R17: 0 | S17: =+VLOOKUP($J17,'Master Data'!$B:$V,21,FALSE)*$H17 -> 17.54 | T17: =+VLOOKUP($K17,'Master Data'!$B:$V,21,FALSE) -> 30 | U17: =+($F17+$O17+$P17+$S17)*0.15 -> 81.375 | V17: =+$F17+$O17+$P17+$Q17+$R17+$S17+$T17+$U17 -> 656.95192
A18: =+A17+1 -> 16 | B18: Black Pepper Powder | C18: काली मिर्च पाउडर | D18: In House Production | E18: =+VLOOKUP($B18,#REF!,2,FALSE)/100 -> #REF! | F18: =+E18*1000 -> #REF! | G18: 1 | H18: =+IF($G18=0.5,1,IF($G18=1,1,$G18)) -> 1 | I18: Brown Kraft Paper with Window & Zipper (25Gm-100Gm) | J18: Bubble Pouch Small | K18: Surface Xpressbees 0.5Kg-Within City | L18: 15 | M18: =1000/G18 -> 1000 | N18: =+VLOOKUP($I18,'Master Data'!$B:$V,21,FALSE) -> 3.16 | O18: =+N18*G18 -> 3.16 | P18: =+'Master Data'!$W$127*$G18 -> 2.2 | Q18: =+'Master Data'!$W$111*$G18 -> 3.0769231 | R18: 0 | S18: =+VLOOKUP($J18,'Master Data'!$B:$V,21,FALSE)*$H18 -> 8.77 | T18: =+VLOOKUP($K18,'Master Data'!$B:$V,21,FALSE) -> 30 | U18: =+($F18+$O18+$P18+$S18)*0.15 -> #REF! | V18: =+$F18+$O18+$P18+$Q18+$R18+$S18+$T18+$U18 -> #REF!
A19: =+A18+1 -> 17 | B19: Coriander Seeds Powder | C19: धनिया पाउडर | D19: In House Production | E19: =+VLOOKUP($B19,#REF!,2,FALSE)/100 -> #REF! | F19: =+E19*1000 -> #REF! | G19: 1 | H19: =+IF($G19=0.5,1,IF($G19=1,1,$G19)) -> 1 | I19: One side Transparent Stand Up with Zipper (25Gm-100Gm) | J19: Bubble Pouch Small | K19: Surface Xpressbees 0.5Kg-Within City | L19: 15 | M19: =1000/G19 -> 1000 | N19: =+VLOOKUP($I19,'Master Data'!$B:$V,21,FALSE) -> 2.23 | O19: =+N19*G19 -> 2.23 | P19: =+'Master Data'!$W$127*$G19 -> 2.2 | Q19: =+'Master Data'!$W$111*$G19 -> 3.0769231 | R19: 0 | S19: =+VLOOKUP($J19,'Master Data'!$B:$V,21,FALSE)*$H19 -> 8.77 | T19: =+VLOOKUP($K19,'Master Data'!$B:$V,21,FALSE) -> 30 | U19: =+($F19+$O19+$P19+$S19)*0.15 -> #REF! | V19: =+$F19+$O19+$P19+$Q19+$R19+$S19+$T19+$U19 -> #REF!
A20: =+A19+1 -> 18 | B20: Cumin Seeds Powder | C20: जीरा पाउडर | D20: In House Production | E20: =+VLOOKUP($B20,#REF!,2,FALSE)/100 -> #REF! | F20: =+E20*1000 -> #REF! | G20: 1 | H20: =+IF($G20=0.5,1,IF($G20=1,1,$G20)) -> 1 | I20: One side Transparent Stand Up with Zipper (25Gm-100Gm) | J20: Bubble Pouch Small | K20: Surface Xpressbees 0.5Kg-Within City | L20: 15 | M20: =1000/G20 -> 1000 | N20: =+VLOOKUP($I20,'Master Data'!$B:$V,21,FALSE) -> 2.23 | O20: =+N20*G20 -> 2.23 | P20: =+'Master Data'!$W$127*$G20 -> 2.2 | Q20: =+'Master Data'!$W$111*$G20 -> 3.0769231 | R20: 0 | S20: =+VLOOKUP($J20,'Master Data'!$B:$V,21,FALSE)*$H20 -> 8.77 | T20: =+VLOOKUP($K20,'Master Data'!$B:$V,21,FALSE) -> 30 | U20: =+($F20+$O20+$P20+$S20)*0.15 -> #REF! | V20: =+$F20+$O20+$P20+$Q20+$R20+$S20+$T20+$U20 -> #REF!
A21: =+A20+1 -> 19 | B21: Coriander Cumin Seeds Powder | C21: धनिया - जीरा पाउडर | D21: In House Production | E21: =+VLOOKUP($B21,#REF!,2,FALSE)/100 -> #REF! | F21: =+E21*1000 -> #REF! | G21: 1 | H21: =+IF($G21=0.5,1,IF($G21=1,1,$G21)) -> 1 | I21: One side Transparent Stand Up with Zipper (25Gm-100Gm) | J21: Bubble Pouch Small | K21: Surface Xpressbees 0.5Kg-Within City | L21: 15 | M21: =1000/G21 -> 1000 | N21: =+VLOOKUP($I21,'Master Data'!$B:$V,21,FALSE) -> 2.23 | O21: =+N21*G21 -> 2.23 | P21: =+'Master Data'!$W$127*$G21 -> 2.2 | Q21: =+'Master Data'!$W$111*$G21 -> 3.0769231 | R21: 0 | S21: =+VLOOKUP($J21,'Master Data'!$B:$V,21,FALSE)*$H21 -> 8.77 | T21: =+VLOOKUP($K21,'Master Data'!$B:$V,21,FALSE) -> 30 | U21: =+($F21+$O21+$P21+$S21)*0.15 -> #REF! | V21: =+$F21+$O21+$P21+$Q21+$R21+$S21+$T21+$U21 -> #REF!
A22: =+A21+1 -> 20 | B22: Red Chilli Powder - Mildly Spicy | C22: लाल मिर्च पाउडर – सौम्य मसालेदार | D22: =+VLOOKUP($B22,'Master Data'!$B$20:$W$197,2,FALSE) -> MS Malagi | E22: =+VLOOKUP($B22,'Master Data'!$B:$V,21,FALSE) -> 0.281 | F22: =+E22*1000 -> 281 | G22: 1 | H22: =+IF($G22=0.5,1,IF($G22=1,1,$G22)) -> 1 | I22: One side Transparent Stand Up with Zipper (25Gm-100Gm) | J22: Bubble Pouch Small | K22: Surface Xpressbees 0.5Kg-Within City | L22: 15 | M22: =1000/G22 -> 1000 | N22: =+VLOOKUP($I22,'Master Data'!$B:$V,21,FALSE) -> 2.23 | O22: =+N22*G22 -> 2.23 | P22: =+'Master Data'!$W$127*$G22 -> 2.2 | Q22: =+'Master Data'!$W$111*$G22 -> 3.0769231 | R22: 0 | S22: =+VLOOKUP($J22,'Master Data'!$B:$V,21,FALSE)*$H22 -> 8.77 | T22: =+VLOOKUP($K22,'Master Data'!$B:$V,21,FALSE) -> 30 | U22: =+($F22+$O22+$P22+$S22)*0.15 -> 44.13 | V22: =+$F22+$O22+$P22+$Q22+$R22+$S22+$T22+$U22 -> 371.40692
A23: =+A22+1 -> 21 | B23: Red Chilli Powder - Medium Spicy | C23: लाल मिर्च पाउडर मध्यम मसालेदार | D23: =+VLOOKUP($B23,'Master Data'!$B$20:$W$197,2,FALSE) -> MS Malagi | E23: =+VLOOKUP($B23,'Master Data'!$B:$V,21,FALSE) -> 0.286 | F23: =+E23*1000 -> 286 | G23: 1 | H23: =+IF($G23=0.5,1,IF($G23=1,1,$G23)) -> 1 | I23: One side Transparent Flat Bottom with Zipper (1000Gm) | J23: Recycle Box | K23: NA | L23: 15 | M23: =1000/G23 -> 1000 | N23: =+VLOOKUP($I23,'Master Data'!$B:$V,21,FALSE) -> 11.94 | O23: =+N23*G23 -> 11.94 | P23: =+'Master Data'!$W$127*$G23 -> 2.2 | Q23: =+'Master Data'!$W$111*$G23 -> 3.0769231 | R23: 0 | S23: =+VLOOKUP($J23,'Master Data'!$B:$V,21,FALSE)*$H23 -> 0 | T23: =+VLOOKUP($K23,'Master Data'!$B:$V,21,FALSE) -> #N/A | U23: =+($F23+$O23+$P23+$S23)*0.15 -> 45.021 | V23: =+$F23+$O23+$P23+$Q23+$R23+$S23+$T23+$U23 -> #N/A
A24: =+A23+1 -> 22 | B24: Red Chilli Powder - Very Spicy | C24: लाल मिर्च पाउडर – तीव्र मसालेदार | D24: =+VLOOKUP($B24,'Master Data'!$B$20:$W$197,2,FALSE) -> MS Malagi | E24: =+VLOOKUP($B24,'Master Data'!$B:$V,21,FALSE) -> 0.281 | F24: =+E24*1000 -> 281 | G24: 1 | H24: =+IF($G24=0.5,1,IF($G24=1,1,$G24)) -> 1 | I24: One side Transparent Stand Up with Zipper (25Gm-100Gm) | J24: Bubble Pouch Small | K24: Surface Xpressbees 0.5Kg-Within City | L24: 15 | M24: =1000/G24 -> 1000 | N24: =+VLOOKUP($I24,'Master Data'!$B:$V,21,FALSE) -> 2.23 | O24: =+N24*G24 -> 2.23 | P24: =+'Master Data'!$W$127*$G24 -> 2.2 | Q24: =+'Master Data'!$W$111*$G24 -> 3.0769231 | R24: 0 | S24: =+VLOOKUP($J24,'Master Data'!$B:$V,21,FALSE)*$H24 -> 8.77 | T24: =+VLOOKUP($K24,'Master Data'!$B:$V,21,FALSE) -> 30 | U24: =+($F24+$O24+$P24+$S24)*0.15 -> 44.13 | V24: =+$F24+$O24+$P24+$Q24+$R24+$S24+$T24+$U24 -> 371.40692
A25: =+A24+1 -> 23 | B25: Red Chilli Powder - Premium Kashmiri | C25: लाल मिर्च पाउडर – प्रीमियम कश्मीरी | D25: =+VLOOKUP($B25,'Master Data'!$B$20:$W$197,2,FALSE) -> MS Malagi | E25: =+VLOOKUP($B25,'Master Data'!$B:$V,21,FALSE) -> 0.601 | F25: =+E25*1000 -> 601 | G25: 1 | H25: =+IF($G25=0.5,1,IF($G25=1,1,$G25)) -> 1 | I25: One side Transparent Stand Up with Zipper (25Gm-100Gm) | J25: Bubble Pouch Small | K25: Surface Xpressbees 0.5Kg-Within City | L25: 15 | M25: =1000/G25 -> 1000 | N25: =+VLOOKUP($I25,'Master Data'!$B:$V,21,FALSE) -> 2.23 | O25: =+N25*G25 -> 2.23 | P25: =+'Master Data'!$W$127*$G25 -> 2.2 | Q25: =+'Master Data'!$W$111*$G25 -> 3.0769231 | R25: 0 | S25: =+VLOOKUP($J25,'Master Data'!$B:$V,21,FALSE)*$H25 -> 8.77 | T25: =+VLOOKUP($K25,'Master Data'!$B:$V,21,FALSE) -> 30 | U25: =+($F25+$O25+$P25+$S25)*0.15 -> 92.13 | V25: =+$F25+$O25+$P25+$Q25+$R25+$S25+$T25+$U25 -> 739.40692
A26: =+A25+1 -> 24 | B26: Turmeric Powder - Erode | C26: हल्दी पाउडर - इरोड | D26: =+VLOOKUP($B26,'Master Data'!$B$20:$W$197,2,FALSE) -> SMR | E26: =+VLOOKUP($B26,'Master Data'!$B:$V,21,FALSE) -> 0.217 | F26: =+E26*1000 -> 217 | G26: 1 | H26: =+IF($G26=0.5,1,IF($G26=1,1,$G26)) -> 1 | I26: One side Transparent Stand Up with Zipper (25Gm-100Gm) | J26: Bubble Pouch Small | K26: Surface Xpressbees 0.5Kg-Within City | L26: 15 | M26: =1000/G26 -> 1000 | N26: =+VLOOKUP($I26,'Master Data'!$B:$V,21,FALSE) -> 2.23 | O26: =+N26*G26 -> 2.23 | P26: =+'Master Data'!$W$127*$G26 -> 2.2 | Q26: =+'Master Data'!$W$111*$G26 -> 3.0769231 | R26: 0 | S26: =+VLOOKUP($J26,'Master Data'!$B:$V,21,FALSE)*$H26 -> 8.77 | T26: =+VLOOKUP($K26,'Master Data'!$B:$V,21,FALSE) -> 30 | U26: =+($F26+$O26+$P26+$S26)*0.15 -> 34.53 | V26: =+$F26+$O26+$P26+$Q26+$R26+$S26+$T26+$U26 -> 297.80692
A27: =+A26+1 -> 25 | B27: Turmeric Powder - Lakadong | C27: हल्दी पाउडर - लकडोंग | D27: =+VLOOKUP($B27,'Master Data'!$B$20:$W$197,2,FALSE) -> Na Risa | E27: =+VLOOKUP($B27,'Master Data'!$B:$V,21,FALSE) -> 0.447 | F27: =+E27*1000 -> 447 | G27: 1 | H27: =+IF($G27=0.5,1,IF($G27=1,1,$G27)) -> 1 | I27: One side Transparent Stand Up with Zipper (25Gm-100Gm) | J27: Bubble Pouch Small | K27: Surface Xpressbees 0.5Kg-Within City | L27: 15 | M27: =1000/G27 -> 1000 | N27: =+VLOOKUP($I27,'Master Data'!$B:$V,21,FALSE) -> 2.23 | O27: =+N27*G27 -> 2.23 | P27: =+'Master Data'!$W$127*$G27 -> 2.2 | Q27: =+'Master Data'!$W$111*$G27 -> 3.0769231 | R27: 0 | S27: =+VLOOKUP($J27,'Master Data'!$B:$V,21,FALSE)*$H27 -> 8.77 | T27: =+VLOOKUP($K27,'Master Data'!$B:$V,21,FALSE) -> 30 | U27: =+($F27+$O27+$P27+$S27)*0.15 -> 69.03 | V27: =+$F27+$O27+$P27+$Q27+$R27+$S27+$T27+$U27 -> 562.30692
A28: =+A27+1 -> 26 | B28: Asafoetida | C28: हींग | D28: =+VLOOKUP($B28,'Master Data'!$B$20:$W$197,2,FALSE) -> Chandan Enterprise | E28: =+VLOOKUP($B28,'Master Data'!$B:$V,21,FALSE) -> 0.538 | F28: =+E28*1000 -> 538 | G28: 1 | H28: =+IF($G28=0.5,1,IF($G28=1,1,$G28)) -> 1 | I28: One side Transparent Stand Up with Zipper (25Gm-100Gm) | J28: Bubble Pouch Small | K28: Surface Xpressbees 0.5Kg-Within City | L28: 15 | M28: =1000/G28 -> 1000 | N28: =+VLOOKUP($I28,'Master Data'!$B:$V,21,FALSE) -> 2.23 | O28: =+N28*G28 -> 2.23 | P28: =+'Master Data'!$W$127*$G28 -> 2.2 | Q28: =+'Master Data'!$W$111*$G28 -> 3.0769231 | R28: 0 | S28: =+VLOOKUP($J28,'Master Data'!$B:$V,21,FALSE)*$H28 -> 8.77 | T28: =+VLOOKUP($K28,'Master Data'!$B:$V,21,FALSE) -> 30 | U28: =+($F28+$O28+$P28+$S28)*0.15 -> 82.68 | V28: =+$F28+$O28+$P28+$Q28+$R28+$S28+$T28+$U28 -> 666.95692
A29: =+A28+1 -> 27 | B29: Chaat Masala | C29: चाट मसाला | D29: In House Production | E29: =+VLOOKUP($B29,#REF!,2,FALSE)/100 -> #REF! | F29: =+E29*1000 -> #REF! | G29: 1 | H29: =+IF($G29=0.5,1,IF($G29=1,1,$G29)) -> 1 | I29: One side Transparent Stand Up with Zipper (25Gm-100Gm) | J29: Bubble Pouch Small | K29: Surface Xpressbees 0.5Kg-Within City | L29: 15 | M29: =1000/G29 -> 1000 | N29: =+VLOOKUP($I29,'Master Data'!$B:$V,21,FALSE) -> 2.23 | O29: =+N29*G29 -> 2.23 | P29: =+'Master Data'!$W$127*$G29 -> 2.2 | Q29: =+'Master Data'!$W$111*$G29 -> 3.0769231 | R29: 0 | S29: =+VLOOKUP($J29,'Master Data'!$B:$V,21,FALSE)*$H29 -> 8.77 | T29: =+VLOOKUP($K29,'Master Data'!$B:$V,21,FALSE) -> 30 | U29: =+($F29+$O29+$P29+$S29)*0.15 -> #REF! | V29: =+$F29+$O29+$P29+$Q29+$R29+$S29+$T29+$U29 -> #REF!
A30: =+A29+1 -> 28 | B30: Punjabi Chole Masala | C30: पंजाबी चना मसाला | D30: In House Production | E30: =+VLOOKUP($B30,#REF!,2,FALSE)/100 -> #REF! | F30: =+E30*1000 -> #REF! | G30: 40 | H30: =+IF($G30=0.5,1,IF($G30=1,1,$G30)) -> 40 | I30: Brown Kraft Paper with Window & Zipper (25Gm-100Gm) | J30: Recycle Box | K30: NA | L30: 15 | M30: =1000/G30 -> 25 | N30: =+VLOOKUP($I30,'Master Data'!$B:$V,21,FALSE) -> 3.16 | O30: =+N30*G30 -> 126.4 | P30: =+'Master Data'!$W$127*$G30 -> 88 | Q30: =+'Master Data'!$W$111*$G30 -> 123.07692 | R30: 0 | S30: =+VLOOKUP($J30,'Master Data'!$B:$V,21,FALSE)*$H30 -> 0 | T30: =+VLOOKUP($K30,'Master Data'!$B:$V,21,FALSE) -> #N/A | U30: =+($F30+$O30+$P30+$S30)*0.15 -> #REF! | V30: =+$F30+$O30+$P30+$Q30+$R30+$S30+$T30+$U30 -> #REF!
A31: =+A30+1 -> 29 | B31: Garam Masala | C31: गरम मसाला | D31: In House Production | E31: =+VLOOKUP($B31,#REF!,2,FALSE)/100 -> #REF! | F31: =+E31*1000 -> #REF! | G31: 1 | H31: =+IF($G31=0.5,1,IF($G31=1,1,$G31)) -> 1 | I31: One side Transparent Stand Up with Zipper (25Gm-100Gm) | J31: Bubble Pouch Small | K31: Surface Xpressbees 0.5Kg-Within City | L31: 15 | M31: =1000/G31 -> 1000 | N31: =+VLOOKUP($I31,'Master Data'!$B:$V,21,FALSE) -> 2.23 | O31: =+N31*G31 -> 2.23 | P31: =+'Master Data'!$W$127*$G31 -> 2.2 | Q31: =+'Master Data'!$W$111*$G31 -> 3.0769231 | R31: 0 | S31: =+VLOOKUP($J31,'Master Data'!$B:$V,21,FALSE)*$H31 -> 8.77 | T31: =+VLOOKUP($K31,'Master Data'!$B:$V,21,FALSE) -> 30 | U31: =+($F31+$O31+$P31+$S31)*0.15 -> #REF! | V31: =+$F31+$O31+$P31+$Q31+$R31+$S31+$T31+$U31 -> #REF!
A32: =+A31+1 -> 30 | B32: Rasam Masala Powder | C32: रसम मसाला | D32: In House Production | E32: =+VLOOKUP($B32,#REF!,2,FALSE)/100 -> #REF! | F32: =+E32*1000 -> #REF! | G32: 1 | H32: =+IF($G32=0.5,1,IF($G32=1,1,$G32)) -> 1 | I32: One side Transparent Stand Up with Zipper (25Gm-100Gm) | J32: Bubble Pouch Small | K32: Surface Xpressbees 0.5Kg-Within City | L32: 15 | M32: =1000/G32 -> 1000 | N32: =+VLOOKUP($I32,'Master Data'!$B:$V,21,FALSE) -> 2.23 | O32: =+N32*G32 -> 2.23 | P32: =+'Master Data'!$W$127*$G32 -> 2.2 | Q32: =+'Master Data'!$W$111*$G32 -> 3.0769231 | R32: 0 | S32: =+VLOOKUP($J32,'Master Data'!$B:$V,21,FALSE)*$H32 -> 8.77 | T32: =+VLOOKUP($K32,'Master Data'!$B:$V,21,FALSE) -> 30 | U32: =+($F32+$O32+$P32+$S32)*0.15 -> #REF! | V32: =+$F32+$O32+$P32+$Q32+$R32+$S32+$T32+$U32 -> #REF!
A33: =+A32+1 -> 31 | B33: Sambar Masala Powder | C33: सांभर मसाला | D33: In House Production | E33: =+VLOOKUP($B33,#REF!,2,FALSE)/100 -> #REF! | F33: =+E33*1000 -> #REF! | G33: 1 | H33: =+IF($G33=0.5,1,IF($G33=1,1,$G33)) -> 1 | I33: One side Transparent Stand Up with Zipper (25Gm-100Gm) | J33: Bubble Pouch Small | K33: Surface Xpressbees 0.5Kg-Within City | L33: 15 | M33: =1000/G33 -> 1000 | N33: =+VLOOKUP($I33,'Master Data'!$B:$V,21,FALSE) -> 2.23 | O33: =+N33*G33 -> 2.23 | P33: =+'Master Data'!$W$127*$G33 -> 2.2 | Q33: =+'Master Data'!$W$111*$G33 -> 3.0769231 | R33: 0 | S33: =+VLOOKUP($J33,'Master Data'!$B:$V,21,FALSE)*$H33 -> 8.77 | T33: =+VLOOKUP($K33,'Master Data'!$B:$V,21,FALSE) -> 30 | U33: =+($F33+$O33+$P33+$S33)*0.15 -> #REF! | V33: =+$F33+$O33+$P33+$Q33+$R33+$S33+$T33+$U33 -> #REF!
A34: =+A33+1 -> 32 | B34: Sabji Masala Powder | C34: सब्जी मसाला | D34: In House Production | E34: =+VLOOKUP($B34,#REF!,2,FALSE)/100 -> #REF! | F34: =+E34*1000 -> #REF! | G34: 1 | H34: =+IF($G34=0.5,1,IF($G34=1,1,$G34)) -> 1 | I34: One side Transparent Stand Up with Zipper (25Gm-100Gm) | J34: Bubble Pouch Small | K34: Surface Xpressbees 0.5Kg-Within City | L34: 15 | M34: =1000/G34 -> 1000 | N34: =+VLOOKUP($I34,'Master Data'!$B:$V,21,FALSE) -> 2.23 | O34: =+N34*G34 -> 2.23 | P34: =+'Master Data'!$W$127*$G34 -> 2.2 | Q34: =+'Master Data'!$W$111*$G34 -> 3.0769231 | R34: 0 | S34: =+VLOOKUP($J34,'Master Data'!$B:$V,21,FALSE)*$H34 -> 8.77 | T34: =+VLOOKUP($K34,'Master Data'!$B:$V,21,FALSE) -> 30 | U34: =+($F34+$O34+$P34+$S34)*0.15 -> #REF! | V34: =+$F34+$O34+$P34+$Q34+$R34+$S34+$T34+$U34 -> #REF!
A35: =+A34+1 -> 33 | B35: Pav Bhaji Masala | C35: पाव भाजी मसाला | D35: In House Production | E35: =+VLOOKUP($B35,#REF!,2,FALSE)/100 -> #REF! | F35: =+E35*1000 -> #REF! | G35: 1 | H35: =+IF($G35=0.5,1,IF($G35=1,1,$G35)) -> 1 | I35: One side Transparent Stand Up with Zipper (25Gm-100Gm) | J35: Bubble Pouch Small | K35: Surface Xpressbees 0.5Kg-Within City | L35: 15 | M35: =1000/G35 -> 1000 | N35: =+VLOOKUP($I35,'Master Data'!$B:$V,21,FALSE) -> 2.23 | O35: =+N35*G35 -> 2.23 | P35: =+'Master Data'!$W$127*$G35 -> 2.2 | Q35: =+'Master Data'!$W$111*$G35 -> 3.0769231 | R35: 0 | S35: =+VLOOKUP($J35,'Master Data'!$B:$V,21,FALSE)*$H35 -> 8.77 | T35: =+VLOOKUP($K35,'Master Data'!$B:$V,21,FALSE) -> 30 | U35: =+($F35+$O35+$P35+$S35)*0.15 -> #REF! | V35: =+$F35+$O35+$P35+$Q35+$R35+$S35+$T35+$U35 -> #REF!
A36: =+A35+1 -> 34 | B36: Bisibele Bhat Masala | C36: बिसिबेले भात मसाला | D36: In House Production | E36: =+VLOOKUP($B36,#REF!,2,FALSE)/100 -> #REF! | F36: =+E36*1000 -> #REF! | G36: 1 | H36: =+IF($G36=0.5,1,IF($G36=1,1,$G36)) -> 1 | I36: One side Transparent Stand Up with Zipper (25Gm-100Gm) | J36: Bubble Pouch Small | K36: Surface Xpressbees 0.5Kg-Within City | L36: 15 | M36: =1000/G36 -> 1000 | N36: =+VLOOKUP($I36,'Master Data'!$B:$V,21,FALSE) -> 2.23 | O36: =+N36*G36 -> 2.23 | P36: =+'Master Data'!$W$127*$G36 -> 2.2 | Q36: =+'Master Data'!$W$111*$G36 -> 3.0769231 | R36: 0 | S36: =+VLOOKUP($J36,'Master Data'!$B:$V,21,FALSE)*$H36 -> 8.77 | T36: =+VLOOKUP($K36,'Master Data'!$B:$V,21,FALSE) -> 30 | U36: =+($F36+$O36+$P36+$S36)*0.15 -> #REF! | V36: =+$F36+$O36+$P36+$Q36+$R36+$S36+$T36+$U36 -> #REF!
A37: =+A36+1 -> 35 | B37: Premium Chai Masala | C37: प्रीमियम चाय मसाला | D37: In House Production | E37: =+VLOOKUP($B37,#REF!,2,FALSE)/100 -> #REF! | F37: =+E37*1000 -> #REF! | G37: 1 | H37: =+IF($G37=0.5,1,IF($G37=1,1,$G37)) -> 1 | I37: Both Sides Metallic Stand Up Without Zipper (25Gm-100Gm) | J37: Bubble Pouch Small | K37: Surface Xpressbees 0.5Kg-Within City | L37: 15 | M37: =1000/G37 -> 1000 | N37: =+VLOOKUP($I37,'Master Data'!$B:$V,21,FALSE) -> 1.85 | O37: =+N37*G37 -> 1.85 | P37: =+'Master Data'!$W$127*$G37 -> 2.2 | Q37: =+'Master Data'!$W$111*$G37 -> 3.0769231 | R37: 0 | S37: =+VLOOKUP($J37,'Master Data'!$B:$V,21,FALSE)*$H37 -> 8.77 | T37: =+VLOOKUP($K37,'Master Data'!$B:$V,21,FALSE) -> 30 | U37: =+($F37+$O37+$P37+$S37)*0.15 -> #REF! | V37: =+$F37+$O37+$P37+$Q37+$R37+$S37+$T37+$U37 -> #REF!
A38: =+A37+1 -> 36 | B38: Premium Kashmiri Saffron | C38: प्रीमियम कश्मीरी केसर | D38: =+VLOOKUP($B38,'Master Data'!$B$20:$W$197,2,FALSE) -> True Ventures | E38: =+VLOOKUP($B38,'Master Data'!$B:$V,21,FALSE) -> 183.5 | F38: =+E38*1000 -> 183500 | G38: 1 | H38: =+IF($G38=0.5,1,IF($G38=1,1,$G38)) -> 1 | I38: Both Sides Metallic Stand Up Without Zipper (25Gm-100Gm) | J38: Bubble Pouch Small | K38: Surface Xpressbees 1Kg-Within City | L38: 15 | M38: =1000/G38 -> 1000 | N38: =+VLOOKUP($I38,'Master Data'!$B:$V,21,FALSE) -> 1.85 | O38: =+N38*G38 -> 1.85 | P38: =+'Master Data'!$W$127*$G38 -> 2.2 | Q38: =+'Master Data'!$W$111*$G38 -> 3.0769231 | R38: 0 | S38: =+VLOOKUP($J38,'Master Data'!$B:$V,21,FALSE)*$H38 -> 8.77 | T38: =+VLOOKUP($K38,'Master Data'!$B:$V,21,FALSE) -> 54 | U38: =+($F38+$O38+$P38+$S38)*0.15 -> 27526.923 | V38: =+$F38+$O38+$P38+$Q38+$R38+$S38+$T38+$U38 -> 211096.82
A39: =+A38+1 -> 37 | B39: Gun Powder - Without Garlic | C39: गन पाउडर चटनी | D39: In House Production | E39: =+VLOOKUP($B39,#REF!,2,FALSE)/100 -> #REF! | F39: =+E39*1000 -> #REF! | G39: 1 | H39: =+IF($G39=0.5,1,IF($G39=1,1,$G39)) -> 1 | I39: Both Sides Metallic Stand Up Without Zipper (25Gm-100Gm) | J39: Bubble Pouch Small | K39: Surface Xpressbees 0.5Kg-Within City | L39: 15 | M39: =1000/G39 -> 1000 | N39: =+VLOOKUP($I39,'Master Data'!$B:$V,21,FALSE) -> 1.85 | O39: =+N39*G39 -> 1.85 | P39: =+'Master Data'!$W$127*$G39 -> 2.2 | Q39: =+'Master Data'!$W$111*$G39 -> 3.0769231 | R39: 0 | S39: =+VLOOKUP($J39,'Master Data'!$B:$V,21,FALSE)*$H39 -> 8.77 | T39: =+VLOOKUP($K39,'Master Data'!$B:$V,21,FALSE) -> 30 | U39: =+($F39+$O39+$P39+$S39)*0.15 -> #REF! | V39: =+$F39+$O39+$P39+$Q39+$R39+$S39+$T39+$U39 -> #REF!
A40: =+A39+1 -> 38 | B40: Multi-grain Special Chutney Powder | C40: मल्टी ग्रेन स्पेशल चटनी पाउडर | D40: In House Production | E40: =+VLOOKUP($B40,#REF!,2,FALSE)/100 -> #REF! | F40: =+E40*1000 -> #REF! | G40: 1 | H40: =+IF($G40=0.5,1,IF($G40=1,1,$G40)) -> 1 | I40: Both Sides Metallic Stand Up Without Zipper (25Gm-100Gm) | J40: Bubble Pouch Small | K40: Surface Xpressbees 0.5Kg-Within City | L40: 15 | M40: =1000/G40 -> 1000 | N40: =+VLOOKUP($I40,'Master Data'!$B:$V,21,FALSE) -> 1.85 | O40: =+N40*G40 -> 1.85 | P40: =+'Master Data'!$W$127*$G40 -> 2.2 | Q40: =+'Master Data'!$W$111*$G40 -> 3.0769231 | R40: 0 | S40: =+VLOOKUP($J40,'Master Data'!$B:$V,21,FALSE)*$H40 -> 8.77 | T40: =+VLOOKUP($K40,'Master Data'!$B:$V,21,FALSE) -> 30 | U40: =+($F40+$O40+$P40+$S40)*0.15 -> #REF! | V40: =+$F40+$O40+$P40+$Q40+$R40+$S40+$T40+$U40 -> #REF!
...

Sheet Output Sheet
B5: Item | C5: Black Cardamom
B6: Sources | C6: =VLOOKUP($C5,'Production Cost'!$B$2:$D$79,3,FALSE) -> Ali Kikabai
B7: Packing Material for Shipping | C7: Five Ply Box
B8: Size in grams | C8: 1000
B9: Type | C9: Wholesale
B10: Vendor | C10: Maruthi Plastics
B11: Amount | C11: =(VALUE($C$8)*IF($C$6="In House Production",INDEX('Master Data'!$H$552:$J$576,MATCH($C$5,'Master Data'!$H$552:$H$576,0),3),VLOOKUP($C$5,'Master Data'!$B:$W,IF($C$9="Wholesale",21,22),FALSE)))+(VLOOKUP(IF($C$10="Maruthi Plastics",INDEX('Master Data'!$B$202:$L$255,MATCH($C$5,'Master Data'!$B$202:$B$255,0),MATCH(VALUE($C$8),'Master Data'!$B$202:$L$202,0)),INDEX('Master Data'!$B$261:$L$314,MATCH($C$5,'Master Data'!$B$261:$B$314,0),MATCH(VALUE($C$8),'Master Data'!$B$261:$L$261,0))),'Master Data'!$B:$W,IF($C$9="Wholesale",21,22),FALSE)*INDEX('Master Data'!$B$323:$K$376,MATCH($C$5,'Master Data'!$B$323:$B$376,0),MATCH(VALUE($C$8),'Master Data'!$B$323:$K$323,0)))+(IF($C$9="Wholesale",'Master Data'!$V$127*INDEX('Master Data'!$B$323:$K$376,MATCH($C$5,'Master Data'!$B$323:$B$376,0),MATCH(VALUE($C$8),'Master Data'!$B$323:$K$323,0)),'Master Data'!$W$127*INDEX('Master Data'!$B$323:$K$376,MATCH($C$5,'Master Data'!$B$323:$B$376,0),MATCH(VALUE($C$8),'Master Data'!$B$323:$K$323,0))))+(IF($C$9="Wholesale",'Master Data'!$V$111*INDEX('Master Data'!$B$323:$K$376,MATCH($C$5,'Master Data'!$B$323:$B$376,0),MATCH(VALUE($C$8),'Master Data'!$B$323:$K$323,0)),'Master Data'!$W$111*INDEX('Master Data'!$B$323:$K$376,MATCH($C$5,'Master Data'!$B$323:$B$376,0),MATCH(VALUE($C$8),'Master Data'!$B$323:$K$323,0))))+(IF(VALUE($C$8)=1000,'Master Data'!$AF$40,IF(VALUE($C$8)=500,'Master Data'!$AF$39,IF(VALUE($C$8)=250,'Master Data'!$AF$39,'Master Data'!$AF$38))))+(IF(VALUE($C$8)=1000,VLOOKUP($C$7,'Master Data'!$B:$W,IF($C$9="Wholesale",21,22),FALSE),IF(VALUE($C$8)=500,VLOOKUP($C$7,'Master Data'!$B:$W,IF($C$9="Wholesale",21,22),FALSE)/2,IF(VALUE($C$8)=250,VLOOKUP($C$7,'Master Data'!$B:$W,IF($C$9="Wholesale",21,22),FALSE)/3,IF(VALUE($C$8)=100,VLOOKUP($C$7,'Master Data'!$B:$W,IF($C$9="Wholesale",21,22),FALSE)/4,IF(VALUE($C$8)=50,VLOOKUP($C$7,'Master Data'!$B:$W,IF($C$9="Wholesale",21,22),FALSE)/6,IF(VALUE($C$8)=25,VLOOKUP($C$7,'Master Data'!$B:$W,IF($C$9="Wholesale",21,22),FALSE)/8,VLOOKUP($C$7,'Master Data'!$B:$W,IF($C$9="Wholesale",21,22),FALSE)/8)))))))+(IF(VALUE($C$8)=1000,'Master Data'!$AB$32,IF(VALUE($C$8)=500,'Master Data'!$AB$33,IF(VALUE($C$8)=250,'Master Data'!$AB$34,IF(VALUE($C$8)=100,'Master Data'!$AB$35,IF(VALUE($C$8)=50,'Master Data'!$AB$36,IF(VALUE($C$8)=25,'Master Data'!$AB$37,'Master Data'!$AB$38)))))))+(((VALUE($C$8)*IF($C$6="In House Production",INDEX('Master Data'!$H$552:$J$576,MATCH($C$5,'Master Data'!$H$552:$H$576,0),3),VLOOKUP($C$5,'Master Data'!$B:$W,IF($C$9="Wholesale",21,22),FALSE)))+(VLOOKUP(IF($C$10="Maruthi Plastics",INDEX('Master Data'!$B$202:$L$255,MATCH($C$5,'Master Data'!$B$202:$B$255,0),MATCH(VALUE($C$8),'Master Data'!$B$202:$L$202,0)),INDEX('Master Data'!$B$261:$L$314,MATCH($C$5,'Master Data'!$B$261:$B$314,0),MATCH(VALUE($C$8),'Master Data'!$B$261:$L$261,0))),'Master Data'!$B:$W,IF($C$9="Wholesale",21,22),FALSE)*INDEX('Master Data'!$B$323:$K$376,MATCH($C$5,'Master Data'!$B$323:$B$376,0),MATCH(VALUE($C$8),'Master Data'!$B$323:$K$323,0)))+(IF($C$9="Wholesale",'Master Data'!$V$127*INDEX('Master Data'!$B$323:$K$376,MATCH($C$5,'Master Data'!$B$323:$B$376,0),MATCH(VALUE($C$8),'Master Data'!$B$323:$K$323,0)),'Master Data'!$W$127*INDEX('Master Data'!$B$323:$K$376,MATCH($C$5,'Master Data'!$B$323:$B$376,0),MATCH(VALUE($C$8),'Master Data'!$B$323:$K$323,0))))+(IF(VALUE($C$8)=1000,VLOOKUP($C$7,'Master Data'!$B:$W,IF($C$9="Wholesale",21,22),FALSE),IF(VALUE($C$8)=500,VLOOKUP($C$7,'Master Data'!$B:$W,IF($C$9="Wholesale",21,22),FALSE)/2,IF(VALUE($C$8)=250,VLOOKUP($C$7,'Master Data'!$B:$W,IF($C$9="Wholesale",21,22),FALSE)/3,IF(VALUE($C$8)=100,VLOOKUP($C$7,'Master Data'!$B:$W,IF($C$9="Wholesale",21,22),FALSE)/4,IF(VALUE($C$8)=50,VLOOKUP($C$7,'Master Data'!$B:$W,IF($C$9="Wholesale",21,22),FALSE)/6,IF(VALUE($C$8)=25,VLOOKUP($C$7,'Master Data'!$B:$W,IF($C$9="Wholesale",21,22),FALSE)/8,VLOOKUP($C$7,'Master Data'!$B:$W,IF($C$9="Wholesale",21,22),FALSE)/8)))))))+(IF($C$9="Wholesale",'Master Data'!$V$111*INDEX('Master Data'!$B$323:$K$376,MATCH($C$5,'Master Data'!$B$323:$B$376,0),MATCH(VALUE($C$8),'Master Data'!$B$323:$K$323,0)),'Master Data'!$W$111*INDEX('Master Data'!$B$323:$K$376,MATCH($C$5,'Master Data'!$B$323:$B$376,0),MATCH(VALUE($C$8),'Master Data'!$B$323:$K$323,0)))))*(10/100)) -> 2320.5259

Sheet Production Cost
A1: Essence Retail Ventures Private Limited | L1: USA Packaging Cost-MRP Analysis
A2: Sr. No. | B2: Item | C2: Name in Hindi | D2: Sources | E2: Packing Material for Shipping | F2: Size in grams | G2: Type | H2: Vendor | I2: Shipping/Postage | J2: Miscellaneous Costs Percentage | K2: Landed Cost of Goods Per Gm | L2: No. Of Retail Packs Per Kg | M2: No. Of Units Of PM Required for Selected Retail Packs | N2: Packing Material | O2: Qty per Pack | P2: Packaging Cost Per Retail Pack | Q2: Total Packaging Cost | R2: Cost of sticker | S2: Total Labour Cost | T2: Storage Cost | U2: Packaging Material for Shipping | V2: Shipping/Postage | W2: New Shipping/Postage | X2: Miscellaneous Costs | Y2: Total Cost | Z2: Total Cost Per Pack | AA2: Total Cost with New Shipping
A3: 1 | B3: Black Cardamom | C3: काली इलाइची | D3: =+VLOOKUP($B3,'Master Data'!$B$20:$W$197,2,FALSE) -> Ali Kikabai | E3: Recycle Box | F3: 1000 | G3: Wholesale | H3: Maruthi Plastics | I3: Shree Maruthi Couriers-Local | J3: 20 | K3: =IF(D3="In House Production",INDEX('Master Data'!$H$552:$J$580,MATCH('Production Cost'!B3,'Master Data'!$H$552:$H$580,0),3),VLOOKUP($B3,'Master Data'!$B:$W,IF(G3="Wholesale",21,22),FALSE)) -> 1.9586 | L3: 1 | M3: =INDEX('Master Data'!$B$323:$K$376,MATCH('Production Cost'!$B3,'Master Data'!$B$323:$B$376,0),MATCH('Production Cost'!F$3,'Master Data'!$B$323:$K$323,0)) -> 2 | N3: =IF(H3="Maruthi Plastics",INDEX('Master Data'!$B$202:$L$255,MATCH('Production Cost'!B3,'Master Data'!$B$202:$B$255,0),MATCH('Production Cost'!F3,'Master Data'!$B$202:$L$202,0)),INDEX('Master Data'!$B$261:$L$314,MATCH('Production Cost'!B3,'Master Data'!$B$261:$B$314,0),MATCH('Production Cost'!F3,'Master Data'!$B$261:$L$261,0))) -> One side Transparent Flat Bottom with Zipper (1000Gm) | O3: =1000/L3 -> 1000 | P3: =+VLOOKUP($N3,'Master Data'!$B:$W,IF(G3="Wholesale",21,22),FALSE) -> 11.94 | Q3: =+P3*M3 -> 23.88 | R3: =IF(G3="Wholesale",'Master Data'!$V$127*$M3,'Master Data'!$W$127*$M3) -> 4.4 | S3: =IF(G3="Wholesale",'Master Data'!$V$111*$M3,'Master Data'!$W$111*$M3) -> 6.1538462 | T3: =IF(F3=1000,'Master Data'!$AF$40,IF(F3=500,'Master Data'!$AF$39,IF(F3=250,'Master Data'!$AF$39,'Master Data'!$AF$38))) -> 11.116667 | U3: =IF(F3=1000,VLOOKUP($E3,'Master Data'!$B:$W,IF(G3="Wholesale",21,22),FALSE),IF(F3=500,VLOOKUP($E3,'Master Data'!$B:$W,IF(G3="Wholesale",21,22),FALSE)/2,IF(F3=250,VLOOKUP($E3,'Master Data'!$B:$W,IF(G3="Wholesale",21,22),FALSE)/3,IF(F3=100,VLOOKUP($E3,'Master Data'!$B:$W,IF(G3="Wholesale",21,22),FALSE)/4,IF(F3=50,VLOOKUP($E3,'Master Data'!$B:$W,IF(G3="Wholesale",21,22),FALSE)/6,IF(F3=25,VLOOKUP($E3,'Master Data'!$B:$W,IF(G3="Wholesale",21,22),FALSE)/8,VLOOKUP($E3,'Master Data'!$B:$W,IF(G3="Wholesale",21,22),FALSE)/8)))))) -> 0 | V3: =+VLOOKUP($I3,'Master Data'!$B:$V,IF(G3="Wholesale",20,21),FALSE) -> 40 | W3: =IF(F3=1000,'Master Data'!$AB$32,IF(F3=500,'Master Data'!$AB$33,IF(F3=250,'Master Data'!$AB$34,IF(F3=100,'Master Data'!$AB$35,IF(F3=50,'Master Data'!$AB$36,IF(F3=25,'Master Data'!$AB$37,'Master Data'!$AB$38)))))) -> 56.55 | X3: =+((K3*F3)+$Q3+$R3+$U3+$S3+$T3+$W3)*($J3/100) -> 412.1401 | Y3: =+(F3*K3)+Q3+R3+S3+U3+(IF(F3=1000,V3,IF(F3=500,V3/2,IF(F3=250,V3/4,IF(F3=100,V3/10,IF(F3=50,V3/20,V3/40)))))+X3) -> 2445.1739 | Z3: =+Y3/L3 -> 2445.1739 | AA3: =(F3*K3)+Q3+R3+S3+T3+U3+W3+X3 -> 2472.8406 | AB3: =+((K3*F3)+$Q3+$R3+$U3+$S3+$T3)*($J3/100) -> 400.8301 | AC3: =(F3*K3)+Q3+R3+S3+T3+U3+AB3 -> 2404.9806 | AD3: =AC3*1.5 -> 3607.4709
A4: =+A3+1 -> 2 | B4: Green Cardamom | C4: इलायची | D4: =+VLOOKUP($B4,'Master Data'!$B$20:$W$197,2,FALSE) -> Nadha Spices | E4: Recycle Box | F4: 1000 | G4: Wholesale | H4: Maruthi Plastics | I4: Shree Maruthi Couriers-Local | J4: 20 | K4: =IF(D4="In House Production",INDEX('Master Data'!$H$552:$J$580,MATCH('Production Cost'!B4,'Master Data'!$H$552:$H$580,0),3),VLOOKUP($B4,'Master Data'!$B:$W,IF(G4="Wholesale",21,22),FALSE)) -> 3.141 | L4: 1 | M4: =INDEX('Master Data'!$B$323:$K$376,MATCH('Production Cost'!$B4,'Master Data'!$B$323:$B$376,0),MATCH('Production Cost'!F$3,'Master Data'!$B$323:$K$323,0)) -> 2 | N4: =IF(H4="Maruthi Plastics",INDEX('Master Data'!$B$202:$L$255,MATCH('Production Cost'!B4,'Master Data'!$B$202:$B$255,0),MATCH('Production Cost'!F4,'Master Data'!$B$202:$L$202,0)),INDEX('Master Data'!$B$261:$L$314,MATCH('Production Cost'!B4,'Master Data'!$B$261:$B$314,0),MATCH('Production Cost'!F4,'Master Data'!$B$261:$L$261,0))) -> One side Transparent Flat Bottom with Zipper (1000Gm) | O4: =1000/L4 -> 1000 | P4: =+VLOOKUP($N4,'Master Data'!$B:$W,IF(G4="Wholesale",21,22),FALSE) -> 11.94 | Q4: =+P4*M4 -> 23.88 | R4: =IF(G4="Wholesale",'Master Data'!$V$127*$M4,'Master Data'!$W$127*$M4) -> 4.4 | S4: =IF(G4="Wholesale",'Master Data'!$V$111*$M4,'Master Data'!$W$111*$M4) -> 6.1538462 | T4: =IF(F4=1000,'Master Data'!$AF$40,IF(F4=500,'Master Data'!$AF$39,IF(F4=250,'Master Data'!$AF$39,'Master Data'!$AF$38))) -> 11.116667 | U4: =IF(F4=1000,VLOOKUP($E4,'Master Data'!$B:$W,IF(G4="Wholesale",21,22),FALSE),IF(F4=500,VLOOKUP($E4,'Master Data'!$B:$W,IF(G4="Wholesale",21,22),FALSE)/2,IF(F4=250,VLOOKUP($E4,'Master Data'!$B:$W,IF(G4="Wholesale",21,22),FALSE)/3,IF(F4=100,VLOOKUP($E4,'Master Data'!$B:$W,IF(G4="Wholesale",21,22),FALSE)/4,IF(F4=50,VLOOKUP($E4,'Master Data'!$B:$W,IF(G4="Wholesale",21,22),FALSE)/6,IF(F4=25,VLOOKUP($E4,'Master Data'!$B:$W,IF(G4="Wholesale",21,22),FALSE)/8,VLOOKUP($E4,'Master Data'!$B:$W,IF(G4="Wholesale",21,22),FALSE)/8)))))) -> 0 | V4: =+VLOOKUP($I4,'Master Data'!$B:$V,IF(G4="Wholesale",20,21),FALSE) -> 40 | W4: =IF(F4=1000,'Master Data'!$AB$32,IF(F4=500,'Master Data'!$AB$33,IF(F4=250,'Master Data'!$AB$34,IF(F4=100,'Master Data'!$AB$35,IF(F4=50,'Master Data'!$AB$36,IF(F4=25,'Master Data'!$AB$37,'Master Data'!$AB$38)))))) -> 56.55 | X4: =+((K4*F4)+$Q4+$R4+$U4+S4)*($J4/100) -> 635.08677 | Y4: =+(F4*K4)+Q4+R4+S4+U4+(IF(F4=1000,V4,IF(F4=500,V4/2,IF(F4=250,V4/4,IF(F4=100,V4/10,IF(F4=50,V4/20,V4/40)))))+X4) -> 3850.5206 | Z4: =+Y4/L4 -> 3850.5206 | AA4: =(F4*K4)+Q4+R4+S4+T4+U4+W4+X4 -> 3878.1873 | AB4: =+((K4*F4)+$Q4+$R4+$U4+$S4+$T4)*($J4/100) -> 637.3101 | AC4: =(F4*K4)+Q4+R4+S4+T4+U4+AB4 -> 3823.8606 | AD4: =AC4*1.5 -> 5735.7909
A5: =+A4+1 -> 3 | B5: Cassia Cinnamon Rolls For Powdering | C5: कासिया दालचीनी | D5: =+VLOOKUP($B5,'Master Data'!$B$20:$W$197,2,FALSE) -> Ali Kikabai | E5: Recycle Box | F5: 1000 | G5: Wholesale | H5: Maruthi Plastics | I5: Shree Maruthi Couriers-Local | J5: 20 | K5: =IF(D5="In House Production",INDEX('Master Data'!$H$552:$J$580,MATCH('Production Cost'!B5,'Master Data'!$H$552:$H$580,0),3),VLOOKUP($B5,'Master Data'!$B:$W,IF(G5="Wholesale",21,22),FALSE)) -> 0.2886 | L5: 1 | M5: =INDEX('Master Data'!$B$323:$K$376,MATCH('Production Cost'!$B5,'Master Data'!$B$323:$B$376,0),MATCH('Production Cost'!F$3,'Master Data'!$B$323:$K$323,0)) -> 4 | N5: =IF(H5="Maruthi Plastics",INDEX('Master Data'!$B$202:$L$255,MATCH('Production Cost'!B5,'Master Data'!$B$202:$B$255,0),MATCH('Production Cost'!F5,'Master Data'!$B$202:$L$202,0)),INDEX('Master Data'!$B$261:$L$314,MATCH('Production Cost'!B5,'Master Data'!$B$261:$B$314,0),MATCH('Production Cost'!F5,'Master Data'!$B$261:$L$261,0))) -> One side Transparent Flat Bottom with Zipper (1000Gm) | O5: =1000/L5 -> 1000 | P5: =+VLOOKUP($N5,'Master Data'!$B:$W,IF(G5="Wholesale",21,22),FALSE) -> 11.94 | Q5: =+P5*M5 -> 47.76 | R5: =IF(G5="Wholesale",'Master Data'!$V$127*$M5,'Master Data'!$W$127*$M5) -> 8.8 | S5: =IF(G5="Wholesale",'Master Data'!$V$111*$M5,'Master Data'!$W$111*$M5) -> 12.307692 | T5: =IF(F5=1000,'Master Data'!$AF$40,IF(F5=500,'Master Data'!$AF$39,IF(F5=250,'Master Data'!$AF$39,'Master Data'!$AF$38))) -> 11.116667 | U5: =IF(F5=1000,VLOOKUP($E5,'Master Data'!$B:$W,IF(G5="Wholesale",21,22),FALSE),IF(F5=500,VLOOKUP($E5,'Master Data'!$B:$W,IF(G5="Wholesale",21,22),FALSE)/2,IF(F5=250,VLOOKUP($E5,'Master Data'!$B:$W,IF(G5="Wholesale",21,22),FALSE)/3,IF(F5=100,VLOOKUP($E5,'Master Data'!$B:$W,IF(G5="Wholesale",21,22),FALSE)/4,IF(F5=50,VLOOKUP($E5,'Master Data'!$B:$W,IF(G5="Wholesale",21,22),FALSE)/6,IF(F5=25,VLOOKUP($E5,'Master Data'!$B:$W,IF(G5="Wholesale",21,22),FALSE)/8,VLOOKUP($E5,'Master Data'!$B:$W,IF(G5="Wholesale",21,22),FALSE)/8)))))) -> 0 | V5: =+VLOOKUP($I5,'Master Data'!$B:$V,IF(G5="Wholesale",20,21),FALSE) -> 40 | W5: =IF(F5=1000,'Master Data'!$AB$32,IF(F5=500,'Master Data'!$AB$33,IF(F5=250,'Master Data'!$AB$34,IF(F5=100,'Master Data'!$AB$35,IF(F5=50,'Master Data'!$AB$36,IF(F5=25,'Master Data'!$AB$37,'Master Data'!$AB$38)))))) -> 56.55 | X5: =+((K5*F5)+$Q5+$R5+$U5+S5)*($J5/100) -> 71.493538 | Y5: =+(F5*K5)+Q5+R5+S5+U5+(IF(F5=1000,V5,IF(F5=500,V5/2,IF(F5=250,V5/4,IF(F5=100,V5/10,IF(F5=50,V5/20,V5/40)))))+X5) -> 468.96123 | Z5: =+Y5/L5 -> 468.96123 | AA5: =(F5*K5)+Q5+R5+S5+T5+U5+W5+X5 -> 496.6279 | AB5: =+((K5*F5)+$Q5+$R5+$U5+$S5+$T5)*($J5/100) -> 73.716872 | AC5: =(F5*K5)+Q5+R5+S5+T5+U5+AB5 -> 442.30123 | AD5: =AC5*1.5 -> 663.45185
A6: =+A5+1 -> 4 | B6: Cloves | C6: लौंग | D6: =+VLOOKUP($B6,'Master Data'!$B$20:$W$197,2,FALSE) -> Nadha Spices | E6: Recycle Box | F6: 1000 | G6: Wholesale | H6: Maruthi Plastics | I6: Shree Maruthi Couriers-Local | J6: 20 | K6: =IF(D6="In House Production",INDEX('Master Data'!$H$552:$J$580,MATCH('Production Cost'!B6,'Master Data'!$H$552:$H$580,0),3),VLOOKUP($B6,'Master Data'!$B:$W,IF(G6="Wholesale",21,22),FALSE)) -> 1.191 | L6: 1 | M6: =INDEX('Master Data'!$B$323:$K$376,MATCH('Production Cost'!$B6,'Master Data'!$B$323:$B$376,0),MATCH('Production Cost'!F$3,'Master Data'!$B$323:$K$323,0)) -> 2 | N6: =IF(H6="Maruthi Plastics",INDEX('Master Data'!$B$202:$L$255,MATCH('Production Cost'!B6,'Master Data'!$B$202:$B$255,0),MATCH('Production Cost'!F6,'Master Data'!$B$202:$L$202,0)),INDEX('Master Data'!$B$261:$L$314,MATCH('Production Cost'!B6,'Master Data'!$B$261:$B$314,0),MATCH('Production Cost'!F6,'Master Data'!$B$261:$L$261,0))) -> One side Transparent Flat Bottom with Zipper (1000Gm) | O6: =1000/L6 -> 1000 | P6: =+VLOOKUP($N6,'Master Data'!$B:$W,IF(G6="Wholesale",21,22),FALSE) -> 11.94 | Q6: =+P6*M6 -> 23.88 | R6: =IF(G6="Wholesale",'Master Data'!$V$127*$M6,'Master Data'!$W$127*$M6) -> 4.4 | S6: =IF(G6="Wholesale",'Master Data'!$V$111*$M6,'Master Data'!$W$111*$M6) -> 6.1538462 | T6: =IF(F6=1000,'Master Data'!$AF$40,IF(F6=500,'Master Data'!$AF$39,IF(F6=250,'Master Data'!$AF$39,'Master Data'!$AF$38))) -> 11.116667 | U6: =IF(F6=1000,VLOOKUP($E6,'Master Data'!$B:$W,IF(G6="Wholesale",21,22),FALSE),IF(F6=500,VLOOKUP($E6,'Master Data'!$B:$W,IF(G6="Wholesale",21,22),FALSE)/2,IF(F6=250,VLOOKUP($E6,'Master Data'!$B:$W,IF(G6="Wholesale",21,22),FALSE)/3,IF(F6=100,VLOOKUP($E6,'Master Data'!$B:$W,IF(G6="Wholesale",21,22),FALSE)/4,IF(F6=50,VLOOKUP($E6,'Master Data'!$B:$W,IF(G6="Wholesale",21,22),FALSE)/6,IF(F6=25,VLOOKUP($E6,'Master Data'!$B:$W,IF(G6="Wholesale",21,22),FALSE)/8,VLOOKUP($E6,'Master Data'!$B:$W,IF(G6="Wholesale",21,22),FALSE)/8)))))) -> 0 | V6: =+VLOOKUP($I6,'Master Data'!$B:$V,IF(G6="Wholesale",20,21),FALSE) -> 40 | W6: =IF(F6=1000,'Master Data'!$AB$32,IF(F6=500,'Master Data'!$AB$33,IF(F6=250,'Master Data'!$AB$34,IF(F6=100,'Master Data'!$AB$35,IF(F6=50,'Master Data'!$AB$36,IF(F6=25,'Master Data'!$AB$37,'Master Data'!$AB$38)))))) -> 56.55 | X6: =+((K6*F6)+$Q6+$R6+$U6+S6)*($J6/100) -> 245.08677 | Y6: =+(F6*K6)+Q6+R6+S6+U6+(IF(F6=1000,V6,IF(F6=500,V6/2,IF(F6=250,V6/4,IF(F6=100,V6/10,IF(F6=50,V6/20,V6/40)))))+X6) -> 1510.5206 | Z6: =+Y6/L6 -> 1510.5206 | AA6: =(F6*K6)+Q6+R6+S6+T6+U6+W6+X6 -> 1538.1873 | AB6: =+((K6*F6)+$Q6+$R6+$U6+$S6+$T6)*($J6/100) -> 247.3101 | AC6: =(F6*K6)+Q6+R6+S6+T6+U6+AB6 -> 1483.8606 | AD6: =AC6*1.5 -> 2225.7909
A7: =+A6+1 -> 5 | B7: Original Indian Bay Leaf | C7: तेज पत्ता | D7: =+VLOOKUP($B7,'Master Data'!$B$20:$W$197,2,FALSE) -> Ali Kikabai | E7: Recycle Box | F7: 1000 | G7: Wholesale | H7: Maruthi Plastics | I7: Shree Maruthi Couriers-Local | J7: 20 | K7: =IF(D7="In House Production",INDEX('Master Data'!$H$552:$J$580,MATCH('Production Cost'!B7,'Master Data'!$H$552:$H$580,0),3),VLOOKUP($B7,'Master Data'!$B:$W,IF(G7="Wholesale",21,22),FALSE)) -> 0.1736 | L7: 1 | M7: =INDEX('Master Data'!$B$323:$K$376,MATCH('Production Cost'!$B7,'Master Data'!$B$323:$B$376,0),MATCH('Production Cost'!F$3,'Master Data'!$B$323:$K$323,0)) -> 4 | N7: =IF(H7="Maruthi Plastics",INDEX('Master Data'!$B$202:$L$255,MATCH('Production Cost'!B7,'Master Data'!$B$202:$B$255,0),MATCH('Production Cost'!F7,'Master Data'!$B$202:$L$202,0)),INDEX('Master Data'!$B$261:$L$314,MATCH('Production Cost'!B7,'Master Data'!$B$261:$B$314,0),MATCH('Production Cost'!F7,'Master Data'!$B$261:$L$261,0))) -> One side Transparent Flat Bottom with Zipper (1000Gm) | O7: =1000/L7 -> 1000 | P7: =+VLOOKUP($N7,'Master Data'!$B:$W,IF(G7="Wholesale",21,22),FALSE) -> 11.94 | Q7: =+P7*M7 -> 47.76 | R7: =IF(G7="Wholesale",'Master Data'!$V$127*$M7,'Master Data'!$W$127*$M7) -> 8.8 | S7: =IF(G7="Wholesale",'Master Data'!$V$111*$M7,'Master Data'!$W$111*$M7) -> 12.307692 | T7: =IF(F7=1000,'Master Data'!$AF$40,IF(F7=500,'Master Data'!$AF$39,IF(F7=250,'Master Data'!$AF$39,'Master Data'!$AF$38))) -> 11.116667 | U7: =IF(F7=1000,VLOOKUP($E7,'Master Data'!$B:$W,IF(G7="Wholesale",21,22),FALSE),IF(F7=500,VLOOKUP($E7,'Master Data'!$B:$W,IF(G7="Wholesale",21,22),FALSE)/2,IF(F7=250,VLOOKUP($E7,'Master Data'!$B:$W,IF(G7="Wholesale",21,22),FALSE)/3,IF(F7=100,VLOOKUP($E7,'Master Data'!$B:$W,IF(G7="Wholesale",21,22),FALSE)/4,IF(F7=50,VLOOKUP($E7,'Master Data'!$B:$W,IF(G7="Wholesale",21,22),FALSE)/6,IF(F7=25,VLOOKUP($E7,'Master Data'!$B:$W,IF(G7="Wholesale",21,22),FALSE)/8,VLOOKUP($E7,'Master Data'!$B:$W,IF(G7="Wholesale",21,22),FALSE)/8)))))) -> 0 | V7: =+VLOOKUP($I7,'Master Data'!$B:$V,IF(G7="Wholesale",20,21),FALSE) -> 40 | W7: =IF(F7=1000,'Master Data'!$AB$32,IF(F7=500,'Master Data'!$AB$33,IF(F7=250,'Master Data'!$AB$34,IF(F7=100,'Master Data'!$AB$35,IF(F7=50,'Master Data'!$AB$36,IF(F7=25,'Master Data'!$AB$37,'Master Data'!$AB$38)))))) -> 56.55 | X7: =+((K7*F7)+$Q7+$R7+$U7+S7)*($J7/100) -> 48.493538 | Y7: =+(F7*K7)+Q7+R7+S7+U7+(IF(F7=1000,V7,IF(F7=500,V7/2,IF(F7=250,V7/4,IF(F7=100,V7/10,IF(F7=50,V7/20,V7/40)))))+X7) -> 330.96123 | Z7: =+Y7/L7 -> 330.96123 | AA7: =(F7*K7)+Q7+R7+S7+T7+U7+W7+X7 -> 358.6279 | AB7: =+((K7*F7)+$Q7+$R7+$U7+$S7+$T7)*($J7/100) -> 50.716872 | AC7: =(F7*K7)+Q7+R7+S7+T7+U7+AB7 -> 304.30123 | AD7: =AC7*1.5 -> 456.45185
A8: =+A7+1 -> 6 | B8: Original Kerala Cinnamon Flakes | C8: केरला दालचीनी | D8: =+VLOOKUP($B8,'Master Data'!$B$20:$W$197,2,FALSE) -> Eternal Blooms | E8: Recycle Box | F8: 1000 | G8: Wholesale | H8: Maruthi Plastics | I8: Shree Maruthi Couriers-Local | J8: 20 | K8: =IF(D8="In House Production",INDEX('Master Data'!$H$552:$J$580,MATCH('Production Cost'!B8,'Master Data'!$H$552:$H$580,0),3),VLOOKUP($B8,'Master Data'!$B:$W,IF(G8="Wholesale",21,22),FALSE)) -> 1.006 | L8: 1 | M8: =INDEX('Master Data'!$B$323:$K$376,MATCH('Production Cost'!$B8,'Master Data'!$B$323:$B$376,0),MATCH('Production Cost'!F$3,'Master Data'!$B$323:$K$323,0)) -> 4 | N8: =IF(H8="Maruthi Plastics",INDEX('Master Data'!$B$202:$L$255,MATCH('Production Cost'!B8,'Master Data'!$B$202:$B$255,0),MATCH('Production Cost'!F8,'Master Data'!$B$202:$L$202,0)),INDEX('Master Data'!$B$261:$L$314,MATCH('Production Cost'!B8,'Master Data'!$B$261:$B$314,0),MATCH('Production Cost'!F8,'Master Data'!$B$261:$L$261,0))) -> One side Transparent Flat Bottom with Zipper (1000Gm) | O8: =1000/L8 -> 1000 | P8: =+VLOOKUP($N8,'Master Data'!$B:$W,IF(G8="Wholesale",21,22),FALSE) -> 11.94 | Q8: =+P8*M8 -> 47.76 | R8: =IF(G8="Wholesale",'Master Data'!$V$127*$M8,'Master Data'!$W$127*$M8) -> 8.8 | S8: =IF(G8="Wholesale",'Master Data'!$V$111*$M8,'Master Data'!$W$111*$M8) -> 12.307692 | T8: =IF(F8=1000,'Master Data'!$AF$40,IF(F8=500,'Master Data'!$AF$39,IF(F8=250,'Master Data'!$AF$39,'Master Data'!$AF$38))) -> 11.116667 | U8: =IF(F8=1000,VLOOKUP($E8,'Master Data'!$B:$W,IF(G8="Wholesale",21,22),FALSE),IF(F8=500,VLOOKUP($E8,'Master Data'!$B:$W,IF(G8="Wholesale",21,22),FALSE)/2,IF(F8=250,VLOOKUP($E8,'Master Data'!$B:$W,IF(G8="Wholesale",21,22),FALSE)/3,IF(F8=100,VLOOKUP($E8,'Master Data'!$B:$W,IF(G8="Wholesale",21,22),FALSE)/4,IF(F8=50,VLOOKUP($E8,'Master Data'!$B:$W,IF(G8="Wholesale",21,22),FALSE)/6,IF(F8=25,VLOOKUP($E8,'Master Data'!$B:$W,IF(G8="Wholesale",21,22),FALSE)/8,VLOOKUP($E8,'Master Data'!$B:$W,IF(G8="Wholesale",21,22),FALSE)/8)))))) -> 0 | V8: =+VLOOKUP($I8,'Master Data'!$B:$V,IF(G8="Wholesale",20,21),FALSE) -> 40 | W8: =IF(F8=1000,'Master Data'!$AB$32,IF(F8=500,'Master Data'!$AB$33,IF(F8=250,'Master Data'!$AB$34,IF(F8=100,'Master Data'!$AB$35,IF(F8=50,'Master Data'!$AB$36,IF(F8=25,'Master Data'!$AB$37,'Master Data'!$AB$38)))))) -> 56.55 | X8: =+((K8*F8)+$Q8+$R8+$U8+S8)*($J8/100) -> 214.97354 | Y8: =+(F8*K8)+Q8+R8+S8+U8+(IF(F8=1000,V8,IF(F8=500,V8/2,IF(F8=250,V8/4,IF(F8=100,V8/10,IF(F8=50,V8/20,V8/40)))))+X8) -> 1329.8412 | Z8: =+Y8/L8 -> 1329.8412 | AA8: =(F8*K8)+Q8+R8+S8+T8+U8+W8+X8 -> 1357.5079 | AB8: =+((K8*F8)+$Q8+$R8+$U8+$S8+$T8)*($J8/100) -> 217.19687 | AC8: =(F8*K8)+Q8+R8+S8+T8+U8+AB8 -> 1303.1812 | AD8: =AC8*1.5 -> 1954.7718
A9: =+A8+1 -> 7 | B9: Red Chilli Whole - Byadagi | C9: लाल मिर्च - ब्याडगी | D9: =+VLOOKUP($B9,'Master Data'!$B$20:$W$197,2,FALSE) -> MS Malagi | E9: Recycle Box | F9: 1000 | G9: Wholesale | H9: Maruthi Plastics | I9: Shree Maruthi Couriers-Local | J9: 20 | K9: =IF(D9="In House Production",INDEX('Master Data'!$H$552:$J$580,MATCH('Production Cost'!B9,'Master Data'!$H$552:$H$580,0),3),VLOOKUP($B9,'Master Data'!$B:$W,IF(G9="Wholesale",21,22),FALSE)) -> 0.611 | L9: 1 | M9: =INDEX('Master Data'!$B$323:$K$376,MATCH('Production Cost'!$B9,'Master Data'!$B$323:$B$376,0),MATCH('Production Cost'!F$3,'Master Data'!$B$323:$K$323,0)) -> 4 | N9: =IF(H9="Maruthi Plastics",INDEX('Master Data'!$B$202:$L$255,MATCH('Production Cost'!B9,'Master Data'!$B$202:$B$255,0),MATCH('Production Cost'!F9,'Master Data'!$B$202:$L$202,0)),INDEX('Master Data'!$B$261:$L$314,MATCH('Production Cost'!B9,'Master Data'!$B$261:$B$314,0),MATCH('Production Cost'!F9,'Master Data'!$B$261:$L$261,0))) -> One side Transparent Flat Bottom with Zipper (1000Gm) | O9: =1000/L9 -> 1000 | P9: =+VLOOKUP($N9,'Master Data'!$B:$W,IF(G9="Wholesale",21,22),FALSE) -> 11.94 | Q9: =+P9*M9 -> 47.76 | R9: =IF(G9="Wholesale",'Master Data'!$V$127*$M9,'Master Data'!$W$127*$M9) -> 8.8 | S9: =IF(G9="Wholesale",'Master Data'!$V$111*$M9,'Master Data'!$W$111*$M9) -> 12.307692 | T9: =IF(F9=1000,'Master Data'!$AF$40,IF(F9=500,'Master Data'!$AF$39,IF(F9=250,'Master Data'!$AF$39,'Master Data'!$AF$38))) -> 11.116667 | U9: =IF(F9=1000,VLOOKUP($E9,'Master Data'!$B:$W,IF(G9="Wholesale",21,22),FALSE),IF(F9=500,VLOOKUP($E9,'Master Data'!$B:$W,IF(G9="Wholesale",21,22),FALSE)/2,IF(F9=250,VLOOKUP($E9,'Master Data'!$B:$W,IF(G9="Wholesale",21,22),FALSE)/3,IF(F9=100,VLOOKUP($E9,'Master Data'!$B:$W,IF(G9="Wholesale",21,22),FALSE)/4,IF(F9=50,VLOOKUP($E9,'Master Data'!$B:$W,IF(G9="Wholesale",21,22),FALSE)/6,IF(F9=25,VLOOKUP($E9,'Master Data'!$B:$W,IF(G9="Wholesale",21,22),FALSE)/8,VLOOKUP($E9,'Master Data'!$B:$W,IF(G9="Wholesale",21,22),FALSE)/8)))))) -> 0 | V9: =+VLOOKUP($I9,'Master Data'!$B:$V,IF(G9="Wholesale",20,21),FALSE) -> 40 | W9: =IF(F9=1000,'Master Data'!$AB$32,IF(F9=500,'Master Data'!$AB$33,IF(F9=250,'Master Data'!$AB$34,IF(F9=100,'Master Data'!$AB$35,IF(F9=50,'Master Data'!$AB$36,IF(F9=25,'Master Data'!$AB$37,'Master Data'!$AB$38)))))) -> 56.55 | X9: =+((K9*F9)+$Q9+$R9+$U9+S9)*($J9/100) -> 135.97354 | Y9: =+(F9*K9)+Q9+R9+S9+U9+(IF(F9=1000,V9,IF(F9=500,V9/2,IF(F9=250,V9/4,IF(F9=100,V9/10,IF(F9=50,V9/20,V9/40)))))+X9) -> 855.84123 | Z9: =+Y9/L9 -> 855.84123 | AA9: =(F9*K9)+Q9+R9+S9+T9+U9+W9+X9 -> 883.5079 | AB9: =+((K9*F9)+$Q9+$R9+$U9+$S9+$T9)*($J9/100) -> 138.19687 | AC9: =(F9*K9)+Q9+R9+S9+T9+U9+AB9 -> 829.18123 | AD9: =AC9*1.5 -> 1243.7718
